<?xml version="1.0" ?>
<!-- =================================================================================== -->
<!-- |    This document was autogenerated by xacro from ur3e_ag95.urdf.xacro           | -->
<!-- |    EDITING THIS FILE BY HAND IS NOT RECOMMENDED                                 | -->
<!-- =================================================================================== -->
<robot name="ur3e_ag95">
  <!--
    Base UR robot series xacro macro.

    NOTE this is NOT a URDF. It cannot directly be loaded by consumers
    expecting a flattened '.urdf' file. See the top-level '.xacro' for that
    (but note that .xacro must still be processed by the xacro command).

    This file models the base kinematic chain of a UR robot, which then gets
    parameterised by various configuration files to convert it into a UR3(e),
    UR5(e), UR10(e) or UR16e, etc.

    NOTE the default kinematic parameters (i.e., link lengths, frame locations,
    offsets, etc) do not correspond to any particular robot. They are defaults
    only. There WILL be non-zero offsets between the Forward Kinematics results
    in TF (i.e., robot_state_publisher) and the values reported by the Teach
    Pendant.

    For accurate (and robot-specific) transforms, the 'kinematics_parameters_file'
    parameter MUST point to a .yaml file containing the appropriate values for
    the targeted robot.

    If using the UniversalRobots/Universal_Robots_ROS_Driver, follow the steps
    described in the readme of that repository to extract the kinematic
    calibration from the controller and generate the required .yaml file.

    Main author of the migration to yaml configs Ludovic Delval.

    Contributors to previous versions (in no particular order)

     - Denis Stogl
     - Lovro Ivanov
     - Felix Messmer
     - Kelsey Hawkins
     - Wim Meeussen
     - Shaun Edwards
     - Nadia Hammoudeh Garcia
     - Dave Hershberger
     - G. vd. Hoorn
     - Philip Long
     - Dave Coleman
     - Miguel Prada
     - Mathias Luedtke
     - Marcel Schnirring
     - Felix von Drigalski
     - Felix Exner
     - Jimmy Da Silva
     - Ajit Krisshna N L
     - Muhammad Asif Rana
  -->
  <!--
    NOTE the macro defined in this file is NOT part of the public API of this
          package. Users CANNOT rely on this file being available, or stored in
          this location. Nor can they rely on the existence of the macro.
  -->
  <!-- 创建世界链接 -->
  <link name="world"/>
  <ros2_control name="ur3e_ag95" type="system">
    <hardware>
      <plugin>gazebo_ros2_control/GazeboSystem</plugin>
    </hardware>
    <joint name="shoulder_pan_joint">
      <command_interface name="position"/>
      <command_interface name="velocity"/>
      <state_interface name="position">
        <!-- initial position for the FakeSystem and simulation -->
        <param name="initial_value">0.0</param>
      </state_interface>
      <state_interface name="velocity"/>
      <state_interface name="effort"/>
    </joint>
    <joint name="shoulder_lift_joint">
      <command_interface name="position"/>
      <command_interface name="velocity"/>
      <state_interface name="position">
        <!-- initial position for the FakeSystem and simulation -->
        <param name="initial_value">-1.57</param>
      </state_interface>
      <state_interface name="velocity"/>
      <state_interface name="effort"/>
    </joint>
    <joint name="elbow_joint">
      <command_interface name="position"/>
      <command_interface name="velocity"/>
      <state_interface name="position">
        <!-- initial position for the FakeSystem and simulation -->
        <param name="initial_value">0.0</param>
      </state_interface>
      <state_interface name="velocity"/>
      <state_interface name="effort"/>
    </joint>
    <joint name="wrist_1_joint">
      <command_interface name="position"/>
      <command_interface name="velocity"/>
      <state_interface name="position">
        <!-- initial position for the FakeSystem and simulation -->
        <param name="initial_value">-1.57</param>
      </state_interface>
      <state_interface name="velocity"/>
      <state_interface name="effort"/>
    </joint>
    <joint name="wrist_2_joint">
      <command_interface name="position"/>
      <command_interface name="velocity"/>
      <state_interface name="position">
        <!-- initial position for the FakeSystem and simulation -->
        <param name="initial_value">0.0</param>
      </state_interface>
      <state_interface name="velocity"/>
      <state_interface name="effort"/>
    </joint>
    <joint name="wrist_3_joint">
      <command_interface name="position"/>
      <command_interface name="velocity"/>
      <state_interface name="position">
        <!-- initial position for the FakeSystem and simulation -->
        <param name="initial_value">0.0</param>
      </state_interface>
      <state_interface name="velocity"/>
      <state_interface name="effort"/>
    </joint>
  </ros2_control>
  <!-- Add URDF transmission elements (for ros_control) -->
  <!--<xacro:ur_arm_transmission prefix="${prefix}" hw_interface="${transmission_hw_interface}" />-->
  <!-- Placeholder for ros2_control transmission which don't yet exist -->
  <!-- links -  main serial chain -->
  <link name="base_link"/>
  <link name="base_link_inertia">
    <visual>
      <origin rpy="0 0 3.141592653589793" xyz="0 0 0"/>
      <geometry>
        <mesh filename="../meshes/ur3e/visual/base.dae"/>
      </geometry>
    </visual>
    <collision>
      <origin rpy="0 0 3.141592653589793" xyz="0 0 0"/>
      <geometry>
        <mesh filename="../meshes/ur3e/collision/base.stl"/>
      </geometry>
    </collision>
    <inertial>
      <mass value="2.0"/>
      <origin rpy="0 0 0" xyz="0 0 0"/>
      <inertia ixx="0.0030531654454" ixy="0.0" ixz="0.0" iyy="0.0030531654454" iyz="0.0" izz="0.005625"/>
    </inertial>
  </link>
  <link name="shoulder_link">
    <visual>
      <origin rpy="0 0 3.141592653589793" xyz="0 0 0"/>
      <geometry>
        <mesh filename="../meshes/ur3e/visual/shoulder.dae"/>
      </geometry>
    </visual>
    <collision>
      <origin rpy="0 0 3.141592653589793" xyz="0 0 0"/>
      <geometry>
        <mesh filename="../meshes/ur3e/collision/shoulder.stl"/>
      </geometry>
    </collision>
    <inertial>
      <mass value="1.98"/>
      <origin rpy="1.570796326794897 0 0" xyz="0.0 0.0 -0.02"/>
      <inertia ixx="0.0027657" ixy="9.6e-06" ixz="-1.49e-05" iyy="0.0021501" iyz="0.0001873" izz="0.0025626"/>
    </inertial>
  </link>
  <link name="upper_arm_link">
    <visual>
      <origin rpy="1.5707963267948966 0 -1.5707963267948966" xyz="0 0 0.12"/>
      <geometry>
        <mesh filename="../meshes/ur3e/visual/upperarm.dae"/>
      </geometry>
    </visual>
    <collision>
      <origin rpy="1.5707963267948966 0 -1.5707963267948966" xyz="0 0 0.12"/>
      <geometry>
        <mesh filename="../meshes/ur3e/collision/upperarm.stl"/>
      </geometry>
    </collision>
    <inertial>
      <mass value="3.4445"/>
      <origin rpy="0 0 0" xyz="-0.11355 0.0 0.1157"/>
      <inertia ixx="0.0042623" ixy="-4.09e-05" ixz="-0.001496" iyy="0.0460284" iyz="-1.29e-05" izz="0.0448947"/>
    </inertial>
  </link>
  <link name="forearm_link">
    <visual>
      <origin rpy="1.5707963267948966 0 -1.5707963267948966" xyz="0 0 0.027"/>
      <geometry>
        <mesh filename="../meshes/ur3e/visual/forearm.dae"/>
      </geometry>
    </visual>
    <collision>
      <origin rpy="1.5707963267948966 0 -1.5707963267948966" xyz="0 0 0.027"/>
      <geometry>
        <mesh filename="../meshes/ur3e/collision/forearm.stl"/>
      </geometry>
    </collision>
    <inertial>
      <mass value="1.437"/>
      <origin rpy="0 0 0" xyz="-0.1632 0.0 0.0238"/>
      <inertia ixx="0.0010511" ixy="0.0" ixz="-3.31e-05" iyy="0.0113396" iyz="2.2e-06" izz="0.0110895"/>
    </inertial>
  </link>
  <link name="wrist_1_link">
    <visual>
      <origin rpy="1.5707963267948966 0 0" xyz="0 0 -0.104"/>
      <geometry>
        <mesh filename="../meshes/ur3e/visual/wrist1.dae"/>
      </geometry>
    </visual>
    <collision>
      <origin rpy="1.5707963267948966 0 0" xyz="0 0 -0.104"/>
      <geometry>
        <mesh filename="../meshes/ur3e/collision/wrist1.stl"/>
      </geometry>
    </collision>
    <inertial>
      <mass value="0.871"/>
      <origin rpy="1.570796326794897 0 0" xyz="0.0 -0.01 0.0"/>
      <inertia ixx="0.0008174" ixy="-5e-07" ixz="2.1e-06" iyy="0.0006844" iyz="6.17e-05" izz="0.0005497"/>
    </inertial>
  </link>
  <link name="wrist_2_link">
    <visual>
      <origin rpy="0 0 0" xyz="0 0 -0.08535"/>
      <geometry>
        <mesh filename="../meshes/ur3e/visual/wrist2.dae"/>
      </geometry>
    </visual>
    <collision>
      <origin rpy="0 0 0" xyz="0 0 -0.08535"/>
      <geometry>
        <mesh filename="../meshes/ur3e/collision/wrist2.stl"/>
      </geometry>
    </collision>
    <inertial>
      <mass value="0.805"/>
      <origin rpy="-1.570796326794897 0 0" xyz="0.0 0.01 0.0"/>
      <inertia ixx="0.0006059" ixy="-6e-07" ixz="-6e-07" iyy="0.0005837" iyz="-2.71e-05" izz="0.0003831"/>
    </inertial>
  </link>
  <link name="wrist_3_link">
    <visual>
      <origin rpy="1.5707963267948966 0 0" xyz="0 0 -0.0921"/>
      <geometry>
        <mesh filename="../meshes/ur3e/visual/wrist3.dae"/>
      </geometry>
    </visual>
    <collision>
      <origin rpy="1.5707963267948966 0 0" xyz="0 0 -0.0921"/>
      <geometry>
        <mesh filename="../meshes/ur3e/collision/wrist3.stl"/>
      </geometry>
    </collision>
    <inertial>
      <mass value="0.261"/>
      <origin rpy="0 0 0" xyz="0.0 0.0 -0.02"/>
      <inertia ixx="0.000108" ixy="-1e-07" ixz="-1e-07" iyy="0.0001086" iyz="-2e-07" izz="0.0001371"/>
    </inertial>
  </link>
  <!-- base_joint fixes base_link to the environment -->
  <joint name="base_joint" type="fixed">
    <origin rpy="0 0 0" xyz="1.0 0.6 0.745"/>
    <parent link="world"/>
    <child link="base_link"/>
  </joint>
  <!-- joints - main serial chain -->
  <joint name="base_link-base_link_inertia" type="fixed">
    <parent link="base_link"/>
    <child link="base_link_inertia"/>
    <!-- 'base_link' is REP-103 aligned (so X+ forward), while the internal
           frames of the robot/controller have X+ pointing backwards.
           Use the joint between 'base_link' and 'base_link_inertia' (a dummy
           link/frame) to introduce the necessary rotation over Z (of pi rad).
      -->
    <origin rpy="0 0 3.141592653589793" xyz="0 0 0"/>
  </joint>
  <joint name="shoulder_pan_joint" type="revolute">
    <parent link="base_link_inertia"/>
    <child link="shoulder_link"/>
    <origin rpy="0 0 0" xyz="0 0 0.15185"/>
    <axis xyz="0 0 1"/>
    <limit effort="54.0" lower="-6.283185307179586" upper="6.283185307179586" velocity="3.141592653589793"/>
    <dynamics damping="0" friction="0"/>
  </joint>
  <joint name="shoulder_lift_joint" type="revolute">
    <parent link="shoulder_link"/>
    <child link="upper_arm_link"/>
    <origin rpy="1.570796327 0 0" xyz="0 0 0"/>
    <axis xyz="0 0 1"/>
    <limit effort="54.0" lower="-6.283185307179586" upper="6.283185307179586" velocity="3.141592653589793"/>
    <dynamics damping="0" friction="0"/>
  </joint>
  <joint name="elbow_joint" type="revolute">
    <parent link="upper_arm_link"/>
    <child link="forearm_link"/>
    <origin rpy="0 0 0" xyz="-0.24355 0 0"/>
    <axis xyz="0 0 1"/>
    <limit effort="28.0" lower="-3.141592653589793" upper="3.141592653589793" velocity="3.141592653589793"/>
    <dynamics damping="0" friction="0"/>
  </joint>
  <joint name="wrist_1_joint" type="revolute">
    <parent link="forearm_link"/>
    <child link="wrist_1_link"/>
    <origin rpy="0 0 0" xyz="-0.2132 0 0.13105"/>
    <axis xyz="0 0 1"/>
    <limit effort="9.0" lower="-6.283185307179586" upper="6.283185307179586" velocity="6.283185307179586"/>
    <dynamics damping="0" friction="0"/>
  </joint>
  <joint name="wrist_2_joint" type="revolute">
    <parent link="wrist_1_link"/>
    <child link="wrist_2_link"/>
    <origin rpy="1.570796327 0 0" xyz="0 -0.08535 -1.750557762378351e-11"/>
    <axis xyz="0 0 1"/>
    <limit effort="9.0" lower="-6.283185307179586" upper="6.283185307179586" velocity="6.283185307179586"/>
    <dynamics damping="0" friction="0"/>
  </joint>
  <joint name="wrist_3_joint" type="revolute">
    <parent link="wrist_2_link"/>
    <child link="wrist_3_link"/>
    <origin rpy="1.570796326589793 3.141592653589793 3.141592653589793" xyz="0 0.0921 -1.8890025766262e-11"/>
    <axis xyz="0 0 1"/>
    <limit effort="9.0" lower="-6.283185307179586" upper="6.283185307179586" velocity="6.283185307179586"/>
    <dynamics damping="0" friction="0"/>
  </joint>
  <link name="ft_frame"/>
  <joint name="wrist_3_link-ft_frame" type="fixed">
    <parent link="wrist_3_link"/>
    <child link="ft_frame"/>
    <origin rpy="3.141592653589793 0 0" xyz="0 0 0"/>
  </joint>
  <!-- ROS-Industrial 'base' frame - base_link to UR 'Base' Coordinates transform -->
  <link name="base"/>
  <joint name="base_link-base_fixed_joint" type="fixed">
    <!-- Note the rotation over Z of pi radians - as base_link is REP-103
           aligned (i.e., has X+ forward, Y+ left and Z+ up), this is needed
           to correctly align 'base' with the 'Base' coordinate system of
           the UR controller.
      -->
    <origin rpy="0 0 3.141592653589793" xyz="0 0 0"/>
    <parent link="base_link"/>
    <child link="base"/>
  </joint>
  <!-- ROS-Industrial 'flange' frame - attachment point for EEF models -->
  <link name="flange"/>
  <joint name="wrist_3-flange" type="fixed">
    <parent link="wrist_3_link"/>
    <child link="flange"/>
    <origin rpy="0 -1.5707963267948966 -1.5707963267948966" xyz="0 0 0"/>
  </joint>
  <!-- ROS-Industrial 'tool0' frame - all-zeros tool frame -->
  <link name="tool0"/>
  <joint name="flange-tool0" type="fixed">
    <!-- default toolframe - X+ left, Y+ up, Z+ front -->
    <origin rpy="1.5707963267948966 0 1.5707963267948966" xyz="0 0 0"/>
    <parent link="flange"/>
    <child link="tool0"/>
  </joint>

  <!-- 夹爪抓取点的中心 -->
  <link name="grasp_center"/>
  <joint name="tool0-grasp_center" type="fixed">
    <origin rpy="0 0 0" xyz="0 0 0.175"/>
    <parent link="tool0"/>
    <child link="grasp_center"/>
  </joint>

  <!-- this URDF is overly complicated IMO don't bother trying to understand it lol -->
  <!-- base link flange -->
  <link name="ag95_base_link">
    <!-- <inertial>
        <origin xyz="7.892486664218268e-13 9.73814800116557e-05 0.0030311891257515876" rpy="0 0 0" />
        <mass value="0.18321316702693136" />
        <inertia ixx="4e-05" iyy="0.000121" izz="0.000158" ixy="0.0" iyz="0.0" ixz="-0.0" />
      </inertial> -->
    <inertial>
      <origin rpy="0 0 0" xyz="7.892486664218268e-13 9.73814800116557e-05 0.0030311891257515876"/>
      <mass value="0.05335674905975589"/>
      <inertia ixx="1.1649107960000001e-05" ixy="0.0" ixz="-0.0" iyy="3.5238551579e-05" iyz="0.0" izz="4.6013976442e-05"/>
    </inertial>
    <visual>
      <origin rpy="0 0 0" xyz="0 0 0"/>
      <geometry>
        <mesh filename="../meshes/dh_ag95_description/visual/base_link.stl" scale="0.001 0.001 0.001"/>
      </geometry>
      <material name="">
        <color rgba="0.792156862745098 0.819607843137255 0.933333333333333 1"/>
      </material>
    </visual>
    <collision>
      <origin rpy="0 0 0" xyz="0 0 0"/>
      <geometry>
        <mesh filename="../meshes/dh_ag95_description/collision/base_link.stl" scale="0.001 0.001 0.001"/>
      </geometry>
    </collision>
  </link>
  <!-- main body of gripper -->
  <link name="ag95_body">
    <!-- <inertial>
        <origin xyz="0.040363309423792425 0.014263796342398428 0.04377145101823153" rpy="0 0 0" />
        <mass value="2.681074820833332" />
        <inertia ixx="0.003857" iyy="0.004463" izz="0.001562" ixy="-3e-06" iyz="-2e-06" ixz="-9e-06" />
      </inertial> -->
    <inertial>
      <origin rpy="0 0 0" xyz="0.040363309423792425 0.014263796342398428 0.04377145101823153"/>
      <mass value="0.7808032509181286"/>
      <inertia ixx="0.001123265235043" ixy="-8.736830970000001e-07" ixz="-2.621049291e-06" iyy="0.001299749220637" iyz="-5.82455398e-07" izz="0.00045489766583800003"/>
    </inertial>
    <visual>
      <origin rpy="0 0 0" xyz="0.0405 0.0143 -0.0147"/>
      <geometry>
        <mesh filename="../meshes/dh_ag95_description/visual/gripper_body.stl" scale="0.001 0.001 0.001"/>
      </geometry>
      <material name="">
        <color rgba="0.1 0.1 0.1 1"/>
      </material>
    </visual>
    <collision>
      <origin rpy="0 0 0" xyz="0.0405 0.0143 -0.0147"/>
      <geometry>
        <mesh filename="../meshes/dh_ag95_description/collision/gripper_body.stl" scale="0.001 0.001 0.001"/>
      </geometry>
    </collision>
  </link>
  <joint name="ag95_body_joint" type="fixed">
    <origin rpy="0 0 0" xyz="-0.0405 -0.0143 0.0147"/>
    <parent link="ag95_base_link"/>
    <child link="ag95_body"/>
  </joint>
  <link name="grasp_link"/>
  <joint name="grasp_joint" type="fixed">
    <parent link="ag95_base_link"/>
    <child link="grasp_link"/>
    <origin rpy="1.5707963267948966 -1.5707963267948966 0" xyz="0.0 0.0 0.19"/>
  </joint>
  <link name="left_outer_knuckle">
    <inertial>
      <origin rpy="0 0 0" xyz="0.027678515816713697 0.008750002359538555 -4.432690447753185e-07"/>
      <mass value="0.0589066057773107"/>
      <inertia ixx="1e-06" ixy="0.0" ixz="-0.0" iyy="1.7e-05" iyz="0.0" izz="1.7e-05"/>
    </inertial>
    <!-- <inertial>
          <origin xyz="0.027678515816713697 0.008750002359538555 -4.432690447753185e-07" rpy="0 0 0" />
          <mass value="${0.0589066057773107*0.44684369179}" />
          <inertia ixx="${1e-06*0.44684369179}" iyy="${1.7e-05*0.44684369179}" izz="${1.7e-05*0.44684369179}" ixy="${0.0*0.44684369179}" iyz="${0.0*0.44684369179}" ixz="${-0.0*0.44684369179}" />
        </inertial> -->
    <visual>
      <origin rpy="0 0 0" xyz="-0.036673 0.00875 -0.098336"/>
      <geometry>
        <mesh filename="../meshes/dh_ag95_description/visual/outer_knuckle.stl" scale="0.001 0.001 0.001"/>
      </geometry>
      <material name="">
        <color rgba="0.1 0.1 0.1 1"/>
      </material>
    </visual>
    <collision>
      <origin rpy="0 0 0" xyz="-0.036673 0.00875 -0.098336"/>
      <geometry>
        <mesh filename="../meshes/dh_ag95_description/collision/outer_knuckle.stl" scale="0.001 0.001 0.001"/>
      </geometry>
    </collision>
  </link>
  <link name="left_inner_knuckle">
    <inertial>
      <origin rpy="0 0 0" xyz="-0.001773347637755853 0.025399999999162655 0.028950024725163018"/>
      <mass value="0.07116672022913799"/>
      <inertia ixx="3.7e-05" ixy="0.0" ixz="0.0" iyy="1.7e-05" iyz="-0.0" izz="2.1e-05"/>
    </inertial>
    <!-- <inertial>
          <origin xyz="-0.001773347637755853 0.025399999999162655 0.028950024725163018" rpy="0 0 0" />
          <mass value="${0.07116672022913799*0.44684369179}" />
          <inertia ixx="${3.7e-05*0.44684369179}" iyy="${1.7e-05*0.44684369179}" izz="${2.1e-05*0.44684369179}" ixy="${0.0*0.44684369179}" iyz="${-0.0*0.44684369179}" ixz="${0.0*0.44684369179}" />
        </inertial> -->
    <visual>
      <origin rpy="0 0 0" xyz="-0.016 0.0254 -0.10586"/>
      <geometry>
        <mesh filename="../meshes/dh_ag95_description/visual/inner_knuckle.stl" scale="0.001 0.001 0.001"/>
      </geometry>
      <material name="">
        <color rgba="0.1 0.1 0.1 1"/>
      </material>
    </visual>
    <collision>
      <origin rpy="0 0 0" xyz="-0.016 0.0254 -0.10586"/>
      <geometry>
        <mesh filename="../meshes/dh_ag95_description/collision/inner_knuckle.stl" scale="0.001 0.001 0.001"/>
      </geometry>
    </collision>
  </link>
  <link name="left_finger">
    <inertial>
      <origin rpy="0 0 0" xyz="-0.013763205176003518 0.008750002316393751 0.007315452388518454"/>
      <mass value="0.035304126564626004"/>
      <inertia ixx="2e-06" ixy="0.0" ixz="1e-06" iyy="4e-06" iyz="-0.0" izz="3e-06"/>
    </inertial>
    <!-- <inertial>
          <origin xyz="-0.013763205176003518 0.008750002316393751 0.007315452388518454" rpy="0 0 0" />
          <mass value="${0.035304126564626004*0.14953484502}" />
          <inertia ixx="${2e-06*0.14953484502}" iyy="${4e-06*0.14953484502}" izz="${3e-06*0.14953484502}" ixy="${0.0*0.14953484502}" iyz="${-0.0*0.14953484502}" ixz="${1e-06*0.14953484502}" />
        </inertial> -->
    <visual>
      <origin rpy="0 0 0" xyz="-0.091673 0.00875 -0.098336"/>
      <geometry>
        <mesh filename="../meshes/dh_ag95_description/visual/finger.stl" scale="0.001 0.001 0.001"/>
      </geometry>
      <material name="">
        <color rgba="0.1 0.1 0.1 1"/>
      </material>
    </visual>
    <collision>
      <origin rpy="0 0 0" xyz="-0.091673 0.00875 -0.098336"/>
      <geometry>
        <mesh filename="../meshes/dh_ag95_description/collision/finger.stl" scale="0.001 0.001 0.001"/>
      </geometry>
    </collision>
  </link>
  <link name="left_finger_pad">
    <inertial>
      <origin rpy="0 0 0" xyz="-0.0022695421476374017 2.3166990085415594e-09 0.00779073905191241"/>
      <mass value="0.047823655444711066"/>
      <inertia ixx="5e-06" ixy="-0.0" ixz="0.0" iyy="4e-06" iyz="0.0" izz="2e-06"/>
    </inertial>
    <!-- <inertial>
          <origin xyz="-0.0022695421476374017 2.3166990085415594e-09 0.00779073905191241"
            rpy="0 0 0" />
          <mass value="${0.047823655444711066*0.14953484502}" />
          <inertia ixx="${5e-06*0.14953484502}" iyy="${4e-06*0.14953484502}" izz="${2e-06*0.14953484502}" ixy="${-0.0*0.14953484502}" iyz="${0.0*0.14953484502}" ixz="${0.0*0.14953484502}" />
        </inertial> -->
    <visual>
      <origin rpy="0 0 0" xyz="-0.0705 -0.0 -0.12056"/>
      <geometry>
        <mesh filename="../meshes/dh_ag95_description/visual/finger_pad.stl" scale="0.001 0.001 0.001"/>
      </geometry>
      <material name="">
        <color rgba="0.792156862745098 0.819607843137255 0.933333333333333 1"/>
      </material>
    </visual>
    <collision>
      <origin rpy="0 0 0" xyz="-0.0705 -0.0 -0.12056"/>
      <geometry>
        <mesh filename="../meshes/dh_ag95_description/collision/finger_pad.stl" scale="0.001 0.001 0.001"/>
      </geometry>
    </collision>
  </link>
  <joint name="left_finger_joint" type="revolute">
    <origin rpy="0 0.7800050960087859 0" xyz="0.055 0.0 0.0"/>
    <parent link="left_outer_knuckle"/>
    <child link="left_finger"/>
    <axis xyz="0.0 1.0 -0.0"/>
    <limit effort="50.0" lower="-0.01" upper="0.9400000000000001" velocity="2.1"/>
    <mimic joint="left_outer_knuckle_joint" multiplier="1" offset="0"/>
  </joint>
  <joint name="left_inner_knuckle_joint" type="revolute">
    <origin rpy="0 0.7907912307861107 0.0" xyz="0.0565 -0.0111 0.09116"/>
    <parent link="ag95_body"/>
    <child link="left_inner_knuckle"/>
    <axis xyz="0.0 -1.0 -0.0"/>
    <limit effort="50.0" lower="-0.01" upper="0.9400000000000001" velocity="2.1"/>
    <mimic joint="left_outer_knuckle_joint" multiplier="1" offset="0"/>
  </joint>
  <!-- This joint closes the kinematic loop. Since loops are not allowed in URDF, but they are
      allowed in SDF, this is an SDF fragment. -->
  <gazebo>
    <joint name="left_inner_knuckle_to_finger_joint" type="revolute">
      <pose> -0.020673 0 0.007524 0 0 0</pose>
      <axis>
        <xyz>0 1 0</xyz>
        <use_parent_model_frame>false</use_parent_model_frame>
      </axis>
      <parent>left_inner_knuckle</parent>
      <child>left_finger</child>
    </joint>
  </gazebo>
  <joint name="left_inner_finger_pad_joint" type="fixed">
    <origin rpy="0 0 0" xyz="-0.021173 0.00875 0.022224"/>
    <parent link="left_finger"/>
    <child link="left_finger_pad"/>
  </joint>
  <joint name="left_outer_knuckle_joint" type="revolute">
    <origin rpy="0 -0.7800050960087859 0" xyz="0.077173 0.00555 0.083636"/>
    <parent link="ag95_body"/>
    <child link="left_outer_knuckle"/>
    <axis xyz="-0.0 -1.0 0.0"/>
    <limit effort="50.0" lower="0.0" upper="0.93" velocity="2.1"/>
  </joint>
  <joint name="right_finger_joint" type="revolute">
    <origin rpy="0 0.7800050960087859 0" xyz="0.055 0.0 0.0"/>
    <parent link="right_outer_knuckle"/>
    <child link="right_finger"/>
    <axis xyz="0.0 1.0 -0.0"/>
    <limit effort="50.0" lower="-0.01" upper="0.9400000000000001" velocity="2.1"/>
    <mimic joint="left_outer_knuckle_joint" multiplier="1" offset="0"/>
  </joint>
  <joint name="right_inner_knuckle_joint" type="revolute">
    <origin rpy="0 0.7907912307861107 -3.141592653589793" xyz="0.0245 0.0397 0.09116"/>
    <parent link="ag95_body"/>
    <child link="right_inner_knuckle"/>
    <axis xyz="0.0 -1.0 -0.0"/>
    <limit effort="50.0" lower="-0.01" upper="0.9400000000000001" velocity="2.1"/>
    <mimic joint="left_outer_knuckle_joint" multiplier="1" offset="0"/>
  </joint>
  <!-- This joint closes the kinematic loop. Since loops are not allowed in URDF, but they are
      allowed in SDF, this is an SDF fragment. -->
  <gazebo>
    <joint name="right_inner_knuckle_to_finger_joint" type="revolute">
      <pose> -0.020673 0 0.007524 0 0 0</pose>
      <axis>
        <xyz>0 1 0</xyz>
        <use_parent_model_frame>false</use_parent_model_frame>
      </axis>
      <parent>right_inner_knuckle</parent>
      <child>right_finger</child>
    </joint>
  </gazebo>
  <joint name="right_inner_finger_pad_joint" type="fixed">
    <origin rpy="0 0 0" xyz="-0.021173 0.00875 0.022224"/>
    <parent link="right_finger"/>
    <child link="right_finger_pad"/>
  </joint>
  <link name="right_outer_knuckle">
    <inertial>
      <origin rpy="0 0 0" xyz="0.027678515816713697 0.008750002359538555 -4.432690447753185e-07"/>
      <mass value="0.0589066057773107"/>
      <inertia ixx="1e-06" ixy="0.0" ixz="-0.0" iyy="1.7e-05" iyz="0.0" izz="1.7e-05"/>
    </inertial>
    <!-- <inertial>
          <origin xyz="0.027678515816713697 0.008750002359538555 -4.432690447753185e-07" rpy="0 0 0" />
          <mass value="${0.0589066057773107*0.44684369179}" />
          <inertia ixx="${1e-06*0.44684369179}" iyy="${1.7e-05*0.44684369179}" izz="${1.7e-05*0.44684369179}" ixy="${0.0*0.44684369179}" iyz="${0.0*0.44684369179}" ixz="${-0.0*0.44684369179}" />
        </inertial> -->
    <visual>
      <origin rpy="0 0 0" xyz="-0.036673 0.00875 -0.098336"/>
      <geometry>
        <mesh filename="../meshes/dh_ag95_description/visual/outer_knuckle.stl" scale="0.001 0.001 0.001"/>
      </geometry>
      <material name="">
        <color rgba="0.1 0.1 0.1 1"/>
      </material>
    </visual>
    <collision>
      <origin rpy="0 0 0" xyz="-0.036673 0.00875 -0.098336"/>
      <geometry>
        <mesh filename="../meshes/dh_ag95_description/collision/outer_knuckle.stl" scale="0.001 0.001 0.001"/>
      </geometry>
    </collision>
  </link>
  <link name="right_inner_knuckle">
    <inertial>
      <origin rpy="0 0 0" xyz="-0.001773347637755853 0.025399999999162655 0.028950024725163018"/>
      <mass value="0.07116672022913799"/>
      <inertia ixx="3.7e-05" ixy="0.0" ixz="0.0" iyy="1.7e-05" iyz="-0.0" izz="2.1e-05"/>
    </inertial>
    <!-- <inertial>
          <origin xyz="-0.001773347637755853 0.025399999999162655 0.028950024725163018" rpy="0 0 0" />
          <mass value="${0.07116672022913799*0.44684369179}" />
          <inertia ixx="${3.7e-05*0.44684369179}" iyy="${1.7e-05*0.44684369179}" izz="${2.1e-05*0.44684369179}" ixy="${0.0*0.44684369179}" iyz="${-0.0*0.44684369179}" ixz="${0.0*0.44684369179}" />
        </inertial> -->
    <visual>
      <origin rpy="0 0 0" xyz="-0.016 0.0254 -0.10586"/>
      <geometry>
        <mesh filename="../meshes/dh_ag95_description/visual/inner_knuckle.stl" scale="0.001 0.001 0.001"/>
      </geometry>
      <material name="">
        <color rgba="0.1 0.1 0.1 1"/>
      </material>
    </visual>
    <collision>
      <origin rpy="0 0 0" xyz="-0.016 0.0254 -0.10586"/>
      <geometry>
        <mesh filename="../meshes/dh_ag95_description/collision/inner_knuckle.stl" scale="0.001 0.001 0.001"/>
      </geometry>
    </collision>
  </link>
  <link name="right_finger">
    <inertial>
      <origin rpy="0 0 0" xyz="-0.013763205176003518 0.008750002316393751 0.007315452388518454"/>
      <mass value="0.035304126564626004"/>
      <inertia ixx="2e-06" ixy="0.0" ixz="1e-06" iyy="4e-06" iyz="-0.0" izz="3e-06"/>
    </inertial>
    <!-- <inertial>
          <origin xyz="-0.013763205176003518 0.008750002316393751 0.007315452388518454" rpy="0 0 0" />
          <mass value="${0.035304126564626004*0.14953484502}" />
          <inertia ixx="${2e-06*0.14953484502}" iyy="${4e-06*0.14953484502}" izz="${3e-06*0.14953484502}" ixy="${0.0*0.14953484502}" iyz="${-0.0*0.14953484502}" ixz="${1e-06*0.14953484502}" />
        </inertial> -->
    <visual>
      <origin rpy="0 0 0" xyz="-0.091673 0.00875 -0.098336"/>
      <geometry>
        <mesh filename="../meshes/dh_ag95_description/visual/finger.stl" scale="0.001 0.001 0.001"/>
      </geometry>
      <material name="">
        <color rgba="0.1 0.1 0.1 1"/>
      </material>
    </visual>
    <collision>
      <origin rpy="0 0 0" xyz="-0.091673 0.00875 -0.098336"/>
      <geometry>
        <mesh filename="../meshes/dh_ag95_description/collision/finger.stl" scale="0.001 0.001 0.001"/>
      </geometry>
    </collision>
  </link>
  <link name="right_finger_pad">
    <inertial>
      <origin rpy="0 0 0" xyz="-0.0022695421476374017 2.3166990085415594e-09 0.00779073905191241"/>
      <mass value="0.047823655444711066"/>
      <inertia ixx="5e-06" ixy="-0.0" ixz="0.0" iyy="4e-06" iyz="0.0" izz="2e-06"/>
    </inertial>
    <!-- <inertial>
          <origin xyz="-0.0022695421476374017 2.3166990085415594e-09 0.00779073905191241"
            rpy="0 0 0" />
          <mass value="${0.047823655444711066*0.14953484502}" />
          <inertia ixx="${5e-06*0.14953484502}" iyy="${4e-06*0.14953484502}" izz="${2e-06*0.14953484502}" ixy="${-0.0*0.14953484502}" iyz="${0.0*0.14953484502}" ixz="${0.0*0.14953484502}" />
        </inertial> -->
    <visual>
      <origin rpy="0 0 0" xyz="-0.0705 -0.0 -0.12056"/>
      <geometry>
        <mesh filename="../meshes/dh_ag95_description/visual/finger_pad.stl" scale="0.001 0.001 0.001"/>
      </geometry>
      <material name="">
        <color rgba="0.792156862745098 0.819607843137255 0.933333333333333 1"/>
      </material>
    </visual>
    <collision>
      <origin rpy="0 0 0" xyz="-0.0705 -0.0 -0.12056"/>
      <geometry>
        <mesh filename="../meshes/dh_ag95_description/collision/finger_pad.stl" scale="0.001 0.001 0.001"/>
      </geometry>
    </collision>
  </link>
  <joint name="right_outer_knuckle_joint" type="revolute">
    <origin rpy="0 -0.7800050960087859 3.141592653589793" xyz="0.003827000000000011 0.02305 0.083636"/>
    <parent link="ag95_body"/>
    <child link="right_outer_knuckle"/>
    <axis xyz="-0.0 -1.0 0.0"/>
    <limit effort="50.0" lower="-0.01" upper="0.9400000000000001" velocity="2.1"/>
    <mimic joint="left_outer_knuckle_joint" multiplier="1" offset="0"/>
  </joint>
  <joint name="gripper_base_joint" type="fixed">
    <parent link="tool0"/>
    <child link="ag95_base_link"/>
    <origin rpy="0 0 0" xyz="0 0 0"/>
  </joint>
  <!-- Gazebo plugins -->
  <gazebo>
    <plugin filename="libgazebo_ros2_control.so" name="gazebo_ros2_control">
      <parameters>/home/dylan/ur3e_ag95_ws/install/ur3e_ag95_description/share/ur3e_ag95_description/config/controllers.yaml</parameters>
    </plugin>
  </gazebo>
</robot>
